============================= test session starts =============================
platform win32 -- Python 3.10.7, pytest-7.2.2, pluggy-1.0.0 -- C:\Program Files\Python310\python.exe
cachedir: .pytest_cache
rootdir: C:\Users\Evan\Desktop\github\Autograding\To_Grade
collecting ... collected 2 items

test.py::test_module FAILED                                              [ 50%]
test.py::test_function FAILED                                            [100%]

================================== FAILURES ===================================
_________________________________ test_module _________________________________

    def test_module():
        dir_path = os.path.dirname(os.path.abspath(__file__))
        file_name =os.path.join(dir_path,f"{module_name}.py")
    
    
        expected_output = "expected_output.txt"
    
        result = subprocess.run(["python", file_name], stdout=subprocess.PIPE,stderr = subprocess.PIPE, text = True)
    
        with open(expected_output, "r") as f:
          expected = f.read()
>       assert result.stdout.strip() == expected.strip()
E       AssertionError: assert '' == '1\n2\n3'
E         - 1
E         - 2
E         - 3

test.py:20: AssertionError
________________________________ test_function ________________________________

    def test_function():
    
      #test that function is present in module
>     assert hasattr(module, 'my_fun'), "No 'my_fun' function found"
E     AssertionError: No 'my_fun' function found
E     assert False
E      +  where False = hasattr(module, 'my_fun')

test.py:25: AssertionError
=========================== short test summary info ===========================
FAILED test.py::test_module - AssertionError: assert '' == '1\n2\n3'
FAILED test.py::test_function - AssertionError: No 'my_fun' function found
============================== 2 failed in 0.07s ==============================
